[2023-08-31T04:10:11.919+0000] {logging_mixin.py:150} INFO - Changing /opt/***/logs/dag_id=dags_simple_http_operator/run_id=manual__2023-08-31T04:10:10.160197+00:00/task_id=baywheels_gbfs_info permission to 509
[2023-08-31T04:10:11.920+0000] {logging_mixin.py:150} INFO - Failed to change /opt/***/logs/dag_id=dags_simple_http_operator/run_id=manual__2023-08-31T04:10:10.160197+00:00/task_id=baywheels_gbfs_info permission to 509: [Errno 1] Operation not permitted: '/opt/***/logs/dag_id=dags_simple_http_operator/run_id=manual__2023-08-31T04:10:10.160197+00:00/task_id=baywheels_gbfs_info'
[2023-08-31T04:10:11.987+0000] {logging_mixin.py:150} INFO - Changing /opt/***/logs/dag_id=dags_simple_http_operator/run_id=manual__2023-08-31T04:10:10.160197+00:00/task_id=baywheels_gbfs_info permission to 509
[2023-08-31T04:10:11.988+0000] {logging_mixin.py:150} INFO - Failed to change /opt/***/logs/dag_id=dags_simple_http_operator/run_id=manual__2023-08-31T04:10:10.160197+00:00/task_id=baywheels_gbfs_info permission to 509: [Errno 1] Operation not permitted: '/opt/***/logs/dag_id=dags_simple_http_operator/run_id=manual__2023-08-31T04:10:10.160197+00:00/task_id=baywheels_gbfs_info'
[2023-08-31T04:10:12.142+0000] {taskinstance.py:1103} INFO - Dependencies all met for dep_context=non-requeueable deps ti=<TaskInstance: dags_simple_http_operator.baywheels_gbfs_info manual__2023-08-31T04:10:10.160197+00:00 [queued]>
[2023-08-31T04:10:12.170+0000] {taskinstance.py:1103} INFO - Dependencies all met for dep_context=requeueable deps ti=<TaskInstance: dags_simple_http_operator.baywheels_gbfs_info manual__2023-08-31T04:10:10.160197+00:00 [queued]>
[2023-08-31T04:10:12.172+0000] {taskinstance.py:1308} INFO - Starting attempt 1 of 1
[2023-08-31T04:10:12.232+0000] {taskinstance.py:1327} INFO - Executing <Task(SimpleHttpOperator): baywheels_gbfs_info> on 2023-08-31 04:10:10.160197+00:00
[2023-08-31T04:10:12.237+0000] {standard_task_runner.py:57} INFO - Started process 1885 to run task
[2023-08-31T04:10:12.241+0000] {standard_task_runner.py:84} INFO - Running: ['***', 'tasks', 'run', 'dags_simple_http_operator', 'baywheels_gbfs_info', 'manual__2023-08-31T04:10:10.160197+00:00', '--job-id', '209', '--raw', '--subdir', 'DAGS_FOLDER/dags_simple_http_operator.py', '--cfg-path', '/tmp/tmp57bop4s3']
[2023-08-31T04:10:12.243+0000] {standard_task_runner.py:85} INFO - Job 209: Subtask baywheels_gbfs_info
[2023-08-31T04:10:12.313+0000] {logging_mixin.py:150} INFO - Changing /opt/***/logs/dag_id=dags_simple_http_operator/run_id=manual__2023-08-31T04:10:10.160197+00:00/task_id=baywheels_gbfs_info permission to 509
[2023-08-31T04:10:12.313+0000] {logging_mixin.py:150} INFO - Failed to change /opt/***/logs/dag_id=dags_simple_http_operator/run_id=manual__2023-08-31T04:10:10.160197+00:00/task_id=baywheels_gbfs_info permission to 509: [Errno 1] Operation not permitted: '/opt/***/logs/dag_id=dags_simple_http_operator/run_id=manual__2023-08-31T04:10:10.160197+00:00/task_id=baywheels_gbfs_info'
[2023-08-31T04:10:12.316+0000] {task_command.py:410} INFO - Running <TaskInstance: dags_simple_http_operator.baywheels_gbfs_info manual__2023-08-31T04:10:10.160197+00:00 [running]> on host 07fcf706bef2
[2023-08-31T04:10:12.446+0000] {taskinstance.py:1547} INFO - Exporting env vars: AIRFLOW_CTX_DAG_OWNER='***' AIRFLOW_CTX_DAG_ID='dags_simple_http_operator' AIRFLOW_CTX_TASK_ID='baywheels_gbfs_info' AIRFLOW_CTX_EXECUTION_DATE='2023-08-31T04:10:10.160197+00:00' AIRFLOW_CTX_TRY_NUMBER='1' AIRFLOW_CTX_DAG_RUN_ID='manual__2023-08-31T04:10:10.160197+00:00'
[2023-08-31T04:10:12.448+0000] {http.py:123} INFO - Calling HTTP method
[2023-08-31T04:10:12.456+0000] {base.py:73} INFO - Using connection ID 'gbfs.baywheels.com' for task execution.
[2023-08-31T04:19:02.695+0000] {http.py:226} WARNING - HTTPConnectionPool(host='gbfs.baywheels.com', port=8088): Max retries exceeded with url: /2.3/gbfs.json (Caused by NewConnectionError('<urllib3.connection.HTTPConnection object at 0x7fbb65668310>: Failed to establish a new connection: [Errno 110] Connection timed out')) Tenacity will retry to execute the operation
[2023-08-31T04:19:02.697+0000] {taskinstance.py:1824} ERROR - Task failed with exception
Traceback (most recent call last):
  File "/home/airflow/.local/lib/python3.7/site-packages/urllib3/connection.py", line 175, in _new_conn
    (self._dns_host, self.port), self.timeout, **extra_kw
  File "/home/airflow/.local/lib/python3.7/site-packages/urllib3/util/connection.py", line 95, in create_connection
    raise err
  File "/home/airflow/.local/lib/python3.7/site-packages/urllib3/util/connection.py", line 85, in create_connection
    sock.connect(sa)
TimeoutError: [Errno 110] Connection timed out

During handling of the above exception, another exception occurred:

Traceback (most recent call last):
  File "/home/airflow/.local/lib/python3.7/site-packages/urllib3/connectionpool.py", line 721, in urlopen
    chunked=chunked,
  File "/home/airflow/.local/lib/python3.7/site-packages/urllib3/connectionpool.py", line 415, in _make_request
    conn.request(method, url, **httplib_request_kw)
  File "/home/airflow/.local/lib/python3.7/site-packages/urllib3/connection.py", line 244, in request
    super(HTTPConnection, self).request(method, url, body=body, headers=headers)
  File "/usr/local/lib/python3.7/http/client.py", line 1281, in request
    self._send_request(method, url, body, headers, encode_chunked)
  File "/usr/local/lib/python3.7/http/client.py", line 1327, in _send_request
    self.endheaders(body, encode_chunked=encode_chunked)
  File "/usr/local/lib/python3.7/http/client.py", line 1276, in endheaders
    self._send_output(message_body, encode_chunked=encode_chunked)
  File "/usr/local/lib/python3.7/http/client.py", line 1036, in _send_output
    self.send(msg)
  File "/usr/local/lib/python3.7/http/client.py", line 976, in send
    self.connect()
  File "/home/airflow/.local/lib/python3.7/site-packages/urllib3/connection.py", line 205, in connect
    conn = self._new_conn()
  File "/home/airflow/.local/lib/python3.7/site-packages/urllib3/connection.py", line 187, in _new_conn
    self, "Failed to establish a new connection: %s" % e
urllib3.exceptions.NewConnectionError: <urllib3.connection.HTTPConnection object at 0x7fbb65668310>: Failed to establish a new connection: [Errno 110] Connection timed out

During handling of the above exception, another exception occurred:

Traceback (most recent call last):
  File "/home/airflow/.local/lib/python3.7/site-packages/requests/adapters.py", line 497, in send
    chunked=chunked,
  File "/home/airflow/.local/lib/python3.7/site-packages/urllib3/connectionpool.py", line 799, in urlopen
    method, url, error=e, _pool=self, _stacktrace=sys.exc_info()[2]
  File "/home/airflow/.local/lib/python3.7/site-packages/urllib3/util/retry.py", line 592, in increment
    raise MaxRetryError(_pool, url, error or ResponseError(cause))
urllib3.exceptions.MaxRetryError: HTTPConnectionPool(host='gbfs.baywheels.com', port=8088): Max retries exceeded with url: /2.3/gbfs.json (Caused by NewConnectionError('<urllib3.connection.HTTPConnection object at 0x7fbb65668310>: Failed to establish a new connection: [Errno 110] Connection timed out'))

During handling of the above exception, another exception occurred:

Traceback (most recent call last):
  File "/home/airflow/.local/lib/python3.7/site-packages/airflow/providers/http/operators/http.py", line 125, in execute
    response = http.run(self.endpoint, self.data, self.headers, self.extra_options)
  File "/home/airflow/.local/lib/python3.7/site-packages/airflow/providers/http/hooks/http.py", line 169, in run
    return self.run_and_check(session, prepped_request, extra_options)
  File "/home/airflow/.local/lib/python3.7/site-packages/airflow/providers/http/hooks/http.py", line 227, in run_and_check
    raise ex
  File "/home/airflow/.local/lib/python3.7/site-packages/airflow/providers/http/hooks/http.py", line 219, in run_and_check
    response = session.send(prepped_request, **send_kwargs)
  File "/home/airflow/.local/lib/python3.7/site-packages/requests/sessions.py", line 703, in send
    r = adapter.send(request, **kwargs)
  File "/home/airflow/.local/lib/python3.7/site-packages/requests/adapters.py", line 519, in send
    raise ConnectionError(e, request=request)
requests.exceptions.ConnectionError: HTTPConnectionPool(host='gbfs.baywheels.com', port=8088): Max retries exceeded with url: /2.3/gbfs.json (Caused by NewConnectionError('<urllib3.connection.HTTPConnection object at 0x7fbb65668310>: Failed to establish a new connection: [Errno 110] Connection timed out'))
[2023-08-31T04:19:02.716+0000] {taskinstance.py:1350} INFO - Marking task as FAILED. dag_id=dags_simple_http_operator, task_id=baywheels_gbfs_info, execution_date=20230831T041010, start_date=20230831T041012, end_date=20230831T041902
[2023-08-31T04:19:02.771+0000] {standard_task_runner.py:109} ERROR - Failed to execute job 209 for task baywheels_gbfs_info (HTTPConnectionPool(host='gbfs.baywheels.com', port=8088): Max retries exceeded with url: /2.3/gbfs.json (Caused by NewConnectionError('<urllib3.connection.HTTPConnection object at 0x7fbb65668310>: Failed to establish a new connection: [Errno 110] Connection timed out')); 1885)
[2023-08-31T04:19:02.792+0000] {local_task_job_runner.py:225} INFO - Task exited with return code 1
[2023-08-31T04:19:02.820+0000] {taskinstance.py:2653} INFO - 0 downstream tasks scheduled from follow-on schedule check
