[2023-08-28T21:25:09.990+0000] {logging_mixin.py:150} INFO - Changing /opt/***/logs/dag_id=dags_bash_python_with_xcom/run_id=scheduled__2023-08-27T09:30:00+00:00/task_id=bash_pull permission to 509
[2023-08-28T21:25:09.991+0000] {logging_mixin.py:150} INFO - Failed to change /opt/***/logs/dag_id=dags_bash_python_with_xcom/run_id=scheduled__2023-08-27T09:30:00+00:00/task_id=bash_pull permission to 509: [Errno 1] Operation not permitted: '/opt/***/logs/dag_id=dags_bash_python_with_xcom/run_id=scheduled__2023-08-27T09:30:00+00:00/task_id=bash_pull'
[2023-08-28T21:25:10.064+0000] {logging_mixin.py:150} INFO - Changing /opt/***/logs/dag_id=dags_bash_python_with_xcom/run_id=scheduled__2023-08-27T09:30:00+00:00/task_id=bash_pull permission to 509
[2023-08-28T21:25:10.065+0000] {logging_mixin.py:150} INFO - Failed to change /opt/***/logs/dag_id=dags_bash_python_with_xcom/run_id=scheduled__2023-08-27T09:30:00+00:00/task_id=bash_pull permission to 509: [Errno 1] Operation not permitted: '/opt/***/logs/dag_id=dags_bash_python_with_xcom/run_id=scheduled__2023-08-27T09:30:00+00:00/task_id=bash_pull'
[2023-08-28T21:25:10.223+0000] {taskinstance.py:1103} INFO - Dependencies all met for dep_context=non-requeueable deps ti=<TaskInstance: dags_bash_python_with_xcom.bash_pull scheduled__2023-08-27T09:30:00+00:00 [queued]>
[2023-08-28T21:25:10.232+0000] {taskinstance.py:1103} INFO - Dependencies all met for dep_context=requeueable deps ti=<TaskInstance: dags_bash_python_with_xcom.bash_pull scheduled__2023-08-27T09:30:00+00:00 [queued]>
[2023-08-28T21:25:10.233+0000] {taskinstance.py:1308} INFO - Starting attempt 1 of 1
[2023-08-28T21:25:10.275+0000] {taskinstance.py:1327} INFO - Executing <Task(BashOperator): bash_pull> on 2023-08-27 09:30:00+00:00
[2023-08-28T21:25:10.279+0000] {standard_task_runner.py:57} INFO - Started process 93 to run task
[2023-08-28T21:25:10.283+0000] {standard_task_runner.py:84} INFO - Running: ['***', 'tasks', 'run', 'dags_bash_python_with_xcom', 'bash_pull', 'scheduled__2023-08-27T09:30:00+00:00', '--job-id', '108', '--raw', '--subdir', 'DAGS_FOLDER/dags_bash_python_with_xcom.py', '--cfg-path', '/tmp/tmp0xknc24y']
[2023-08-28T21:25:10.285+0000] {standard_task_runner.py:85} INFO - Job 108: Subtask bash_pull
[2023-08-28T21:25:10.349+0000] {logging_mixin.py:150} INFO - Changing /opt/***/logs/dag_id=dags_bash_python_with_xcom/run_id=scheduled__2023-08-27T09:30:00+00:00/task_id=bash_pull permission to 509
[2023-08-28T21:25:10.350+0000] {logging_mixin.py:150} INFO - Failed to change /opt/***/logs/dag_id=dags_bash_python_with_xcom/run_id=scheduled__2023-08-27T09:30:00+00:00/task_id=bash_pull permission to 509: [Errno 1] Operation not permitted: '/opt/***/logs/dag_id=dags_bash_python_with_xcom/run_id=scheduled__2023-08-27T09:30:00+00:00/task_id=bash_pull'
[2023-08-28T21:25:10.353+0000] {task_command.py:410} INFO - Running <TaskInstance: dags_bash_python_with_xcom.bash_pull scheduled__2023-08-27T09:30:00+00:00 [running]> on host 07fcf706bef2
[2023-08-28T21:25:10.437+0000] {abstractoperator.py:598} ERROR - Exception rendering Jinja template for task 'bash_pull', field 'env'. Template: {'STATUS': '{{ti.xcom_pull(task_ids="python_push")["status"]}}', 'DATA': '{{ti.xcom_pull(task_ids="python_push")["data"]}}', 'OPTIONS_CNT': '{{ti.xcom_pull(task_ids="python_push")["oprionts_cnt"]}}'}
Traceback (most recent call last):
  File "/home/airflow/.local/lib/python3.7/site-packages/airflow/models/abstractoperator.py", line 590, in _do_render_template_fields
    seen_oids,
  File "/home/airflow/.local/lib/python3.7/site-packages/airflow/template/templater.py", line 168, in render_template
    return {k: self.render_template(v, context, jinja_env, oids) for k, v in value.items()}
  File "/home/airflow/.local/lib/python3.7/site-packages/airflow/template/templater.py", line 168, in <dictcomp>
    return {k: self.render_template(v, context, jinja_env, oids) for k, v in value.items()}
  File "/home/airflow/.local/lib/python3.7/site-packages/airflow/template/templater.py", line 156, in render_template
    return self._render(template, context)
  File "/home/airflow/.local/lib/python3.7/site-packages/airflow/models/abstractoperator.py", line 540, in _render
    return super()._render(template, context, dag=dag)
  File "/home/airflow/.local/lib/python3.7/site-packages/airflow/template/templater.py", line 113, in _render
    return render_template_to_string(template, context)
  File "/home/airflow/.local/lib/python3.7/site-packages/airflow/utils/helpers.py", line 288, in render_template_to_string
    return render_template(template, cast(MutableMapping[str, Any], context), native=False)
  File "/home/airflow/.local/lib/python3.7/site-packages/airflow/utils/helpers.py", line 283, in render_template
    return "".join(nodes)
  File "<template>", line 12, in root
  File "/home/airflow/.local/lib/python3.7/site-packages/jinja2/runtime.py", line 852, in _fail_with_undefined_error
    raise self._undefined_exception(self._undefined_message)
jinja2.exceptions.UndefinedError: 'dict object' has no attribute 'oprionts_cnt'
[2023-08-28T21:25:10.439+0000] {taskinstance.py:1824} ERROR - Task failed with exception
Traceback (most recent call last):
  File "/home/airflow/.local/lib/python3.7/site-packages/airflow/models/taskinstance.py", line 1407, in _run_raw_task
    self._execute_task_with_callbacks(context, test_mode)
  File "/home/airflow/.local/lib/python3.7/site-packages/airflow/models/taskinstance.py", line 1531, in _execute_task_with_callbacks
    task_orig = self.render_templates(context=context)
  File "/home/airflow/.local/lib/python3.7/site-packages/airflow/models/taskinstance.py", line 2179, in render_templates
    original_task.render_template_fields(context)
  File "/home/airflow/.local/lib/python3.7/site-packages/airflow/models/baseoperator.py", line 1254, in render_template_fields
    self._do_render_template_fields(self, self.template_fields, context, jinja_env, set())
  File "/home/airflow/.local/lib/python3.7/site-packages/airflow/utils/session.py", line 76, in wrapper
    return func(*args, session=session, **kwargs)
  File "/home/airflow/.local/lib/python3.7/site-packages/airflow/models/abstractoperator.py", line 590, in _do_render_template_fields
    seen_oids,
  File "/home/airflow/.local/lib/python3.7/site-packages/airflow/template/templater.py", line 168, in render_template
    return {k: self.render_template(v, context, jinja_env, oids) for k, v in value.items()}
  File "/home/airflow/.local/lib/python3.7/site-packages/airflow/template/templater.py", line 168, in <dictcomp>
    return {k: self.render_template(v, context, jinja_env, oids) for k, v in value.items()}
  File "/home/airflow/.local/lib/python3.7/site-packages/airflow/template/templater.py", line 156, in render_template
    return self._render(template, context)
  File "/home/airflow/.local/lib/python3.7/site-packages/airflow/models/abstractoperator.py", line 540, in _render
    return super()._render(template, context, dag=dag)
  File "/home/airflow/.local/lib/python3.7/site-packages/airflow/template/templater.py", line 113, in _render
    return render_template_to_string(template, context)
  File "/home/airflow/.local/lib/python3.7/site-packages/airflow/utils/helpers.py", line 288, in render_template_to_string
    return render_template(template, cast(MutableMapping[str, Any], context), native=False)
  File "/home/airflow/.local/lib/python3.7/site-packages/airflow/utils/helpers.py", line 283, in render_template
    return "".join(nodes)
  File "<template>", line 12, in root
  File "/home/airflow/.local/lib/python3.7/site-packages/jinja2/runtime.py", line 852, in _fail_with_undefined_error
    raise self._undefined_exception(self._undefined_message)
jinja2.exceptions.UndefinedError: 'dict object' has no attribute 'oprionts_cnt'
[2023-08-28T21:25:10.446+0000] {taskinstance.py:1350} INFO - Marking task as FAILED. dag_id=dags_bash_python_with_xcom, task_id=bash_pull, execution_date=20230827T093000, start_date=20230828T212510, end_date=20230828T212510
[2023-08-28T21:25:10.476+0000] {standard_task_runner.py:109} ERROR - Failed to execute job 108 for task bash_pull ('dict object' has no attribute 'oprionts_cnt'; 93)
[2023-08-28T21:25:10.495+0000] {local_task_job_runner.py:225} INFO - Task exited with return code 1
[2023-08-28T21:25:10.512+0000] {taskinstance.py:2653} INFO - 0 downstream tasks scheduled from follow-on schedule check
[2023-08-28T21:26:41.150+0000] {logging_mixin.py:150} INFO - Changing /opt/***/logs/dag_id=dags_bash_python_with_xcom/run_id=scheduled__2023-08-27T09:30:00+00:00/task_id=bash_pull permission to 509
[2023-08-28T21:26:41.151+0000] {logging_mixin.py:150} INFO - Failed to change /opt/***/logs/dag_id=dags_bash_python_with_xcom/run_id=scheduled__2023-08-27T09:30:00+00:00/task_id=bash_pull permission to 509: [Errno 1] Operation not permitted: '/opt/***/logs/dag_id=dags_bash_python_with_xcom/run_id=scheduled__2023-08-27T09:30:00+00:00/task_id=bash_pull'
[2023-08-28T21:26:41.192+0000] {logging_mixin.py:150} INFO - Changing /opt/***/logs/dag_id=dags_bash_python_with_xcom/run_id=scheduled__2023-08-27T09:30:00+00:00/task_id=bash_pull permission to 509
[2023-08-28T21:26:41.193+0000] {logging_mixin.py:150} INFO - Failed to change /opt/***/logs/dag_id=dags_bash_python_with_xcom/run_id=scheduled__2023-08-27T09:30:00+00:00/task_id=bash_pull permission to 509: [Errno 1] Operation not permitted: '/opt/***/logs/dag_id=dags_bash_python_with_xcom/run_id=scheduled__2023-08-27T09:30:00+00:00/task_id=bash_pull'
[2023-08-28T21:26:41.362+0000] {taskinstance.py:1103} INFO - Dependencies all met for dep_context=non-requeueable deps ti=<TaskInstance: dags_bash_python_with_xcom.bash_pull scheduled__2023-08-27T09:30:00+00:00 [queued]>
[2023-08-28T21:26:41.372+0000] {taskinstance.py:1103} INFO - Dependencies all met for dep_context=requeueable deps ti=<TaskInstance: dags_bash_python_with_xcom.bash_pull scheduled__2023-08-27T09:30:00+00:00 [queued]>
[2023-08-28T21:26:41.373+0000] {taskinstance.py:1308} INFO - Starting attempt 1 of 1
[2023-08-28T21:26:41.409+0000] {taskinstance.py:1327} INFO - Executing <Task(BashOperator): bash_pull> on 2023-08-27 09:30:00+00:00
[2023-08-28T21:26:41.413+0000] {standard_task_runner.py:57} INFO - Started process 132 to run task
[2023-08-28T21:26:41.416+0000] {standard_task_runner.py:84} INFO - Running: ['***', 'tasks', 'run', 'dags_bash_python_with_xcom', 'bash_pull', 'scheduled__2023-08-27T09:30:00+00:00', '--job-id', '111', '--raw', '--subdir', 'DAGS_FOLDER/dags_bash_python_with_xcom.py', '--cfg-path', '/tmp/tmp0eqxu2vy']
[2023-08-28T21:26:41.418+0000] {standard_task_runner.py:85} INFO - Job 111: Subtask bash_pull
[2023-08-28T21:26:41.482+0000] {logging_mixin.py:150} INFO - Changing /opt/***/logs/dag_id=dags_bash_python_with_xcom/run_id=scheduled__2023-08-27T09:30:00+00:00/task_id=bash_pull permission to 509
[2023-08-28T21:26:41.483+0000] {logging_mixin.py:150} INFO - Failed to change /opt/***/logs/dag_id=dags_bash_python_with_xcom/run_id=scheduled__2023-08-27T09:30:00+00:00/task_id=bash_pull permission to 509: [Errno 1] Operation not permitted: '/opt/***/logs/dag_id=dags_bash_python_with_xcom/run_id=scheduled__2023-08-27T09:30:00+00:00/task_id=bash_pull'
[2023-08-28T21:26:41.486+0000] {task_command.py:410} INFO - Running <TaskInstance: dags_bash_python_with_xcom.bash_pull scheduled__2023-08-27T09:30:00+00:00 [running]> on host 07fcf706bef2
[2023-08-28T21:26:41.635+0000] {taskinstance.py:1547} INFO - Exporting env vars: AIRFLOW_CTX_DAG_OWNER='***' AIRFLOW_CTX_DAG_ID='dags_bash_python_with_xcom' AIRFLOW_CTX_TASK_ID='bash_pull' AIRFLOW_CTX_EXECUTION_DATE='2023-08-27T09:30:00+00:00' AIRFLOW_CTX_TRY_NUMBER='1' AIRFLOW_CTX_DAG_RUN_ID='scheduled__2023-08-27T09:30:00+00:00'
[2023-08-28T21:26:41.637+0000] {subprocess.py:63} INFO - Tmp dir root location: /tmp
[2023-08-28T21:26:41.638+0000] {subprocess.py:75} INFO - Running command: ['/bin/bash', '-c', 'echo $STATUS && echo $DATA && echo $OPTIONS_CNT']
[2023-08-28T21:26:41.646+0000] {subprocess.py:86} INFO - Output:
[2023-08-28T21:26:41.647+0000] {subprocess.py:93} INFO - MyLove
[2023-08-28T21:26:41.648+0000] {subprocess.py:93} INFO - ['Allu', 'Arsenal', 'Myself']
[2023-08-28T21:26:41.648+0000] {subprocess.py:93} INFO - 100
[2023-08-28T21:26:41.649+0000] {subprocess.py:97} INFO - Command exited with return code 0
[2023-08-28T21:26:41.706+0000] {taskinstance.py:1350} INFO - Marking task as SUCCESS. dag_id=dags_bash_python_with_xcom, task_id=bash_pull, execution_date=20230827T093000, start_date=20230828T212641, end_date=20230828T212641
[2023-08-28T21:26:41.749+0000] {local_task_job_runner.py:225} INFO - Task exited with return code 0
[2023-08-28T21:26:41.772+0000] {taskinstance.py:2653} INFO - 0 downstream tasks scheduled from follow-on schedule check
