[2023-08-29T22:12:35.660+0000] {logging_mixin.py:150} INFO - Changing /opt/***/logs/dag_id=dags_python_with_trigger_rule_eg1/run_id=manual__2023-08-29T22:12:33.593926+00:00/task_id=python_upstream_1 permission to 509
[2023-08-29T22:12:35.661+0000] {logging_mixin.py:150} INFO - Failed to change /opt/***/logs/dag_id=dags_python_with_trigger_rule_eg1/run_id=manual__2023-08-29T22:12:33.593926+00:00/task_id=python_upstream_1 permission to 509: [Errno 1] Operation not permitted: '/opt/***/logs/dag_id=dags_python_with_trigger_rule_eg1/run_id=manual__2023-08-29T22:12:33.593926+00:00/task_id=python_upstream_1'
[2023-08-29T22:12:35.739+0000] {logging_mixin.py:150} INFO - Changing /opt/***/logs/dag_id=dags_python_with_trigger_rule_eg1/run_id=manual__2023-08-29T22:12:33.593926+00:00/task_id=python_upstream_1 permission to 509
[2023-08-29T22:12:35.740+0000] {logging_mixin.py:150} INFO - Failed to change /opt/***/logs/dag_id=dags_python_with_trigger_rule_eg1/run_id=manual__2023-08-29T22:12:33.593926+00:00/task_id=python_upstream_1 permission to 509: [Errno 1] Operation not permitted: '/opt/***/logs/dag_id=dags_python_with_trigger_rule_eg1/run_id=manual__2023-08-29T22:12:33.593926+00:00/task_id=python_upstream_1'
[2023-08-29T22:12:35.918+0000] {taskinstance.py:1103} INFO - Dependencies all met for dep_context=non-requeueable deps ti=<TaskInstance: dags_python_with_trigger_rule_eg1.python_upstream_1 manual__2023-08-29T22:12:33.593926+00:00 [queued]>
[2023-08-29T22:12:35.928+0000] {taskinstance.py:1103} INFO - Dependencies all met for dep_context=requeueable deps ti=<TaskInstance: dags_python_with_trigger_rule_eg1.python_upstream_1 manual__2023-08-29T22:12:33.593926+00:00 [queued]>
[2023-08-29T22:12:35.929+0000] {taskinstance.py:1308} INFO - Starting attempt 1 of 1
[2023-08-29T22:12:35.963+0000] {taskinstance.py:1327} INFO - Executing <Task(_PythonDecoratedOperator): python_upstream_1> on 2023-08-29 22:12:33.593926+00:00
[2023-08-29T22:12:35.968+0000] {standard_task_runner.py:57} INFO - Started process 2510 to run task
[2023-08-29T22:12:35.971+0000] {standard_task_runner.py:84} INFO - Running: ['***', 'tasks', 'run', 'dags_python_with_trigger_rule_eg1', 'python_upstream_1', 'manual__2023-08-29T22:12:33.593926+00:00', '--job-id', '162', '--raw', '--subdir', 'DAGS_FOLDER/dags_python_with_trigger_rule_eg1.py', '--cfg-path', '/tmp/tmpnx_r4z53']
[2023-08-29T22:12:35.973+0000] {standard_task_runner.py:85} INFO - Job 162: Subtask python_upstream_1
[2023-08-29T22:12:36.050+0000] {logging_mixin.py:150} INFO - Changing /opt/***/logs/dag_id=dags_python_with_trigger_rule_eg1/run_id=manual__2023-08-29T22:12:33.593926+00:00/task_id=python_upstream_1 permission to 509
[2023-08-29T22:12:36.051+0000] {logging_mixin.py:150} INFO - Failed to change /opt/***/logs/dag_id=dags_python_with_trigger_rule_eg1/run_id=manual__2023-08-29T22:12:33.593926+00:00/task_id=python_upstream_1 permission to 509: [Errno 1] Operation not permitted: '/opt/***/logs/dag_id=dags_python_with_trigger_rule_eg1/run_id=manual__2023-08-29T22:12:33.593926+00:00/task_id=python_upstream_1'
[2023-08-29T22:12:36.054+0000] {task_command.py:410} INFO - Running <TaskInstance: dags_python_with_trigger_rule_eg1.python_upstream_1 manual__2023-08-29T22:12:33.593926+00:00 [running]> on host 07fcf706bef2
[2023-08-29T22:12:36.187+0000] {taskinstance.py:1547} INFO - Exporting env vars: AIRFLOW_CTX_DAG_OWNER='***' AIRFLOW_CTX_DAG_ID='dags_python_with_trigger_rule_eg1' AIRFLOW_CTX_TASK_ID='python_upstream_1' AIRFLOW_CTX_EXECUTION_DATE='2023-08-29T22:12:33.593926+00:00' AIRFLOW_CTX_TRY_NUMBER='1' AIRFLOW_CTX_DAG_RUN_ID='manual__2023-08-29T22:12:33.593926+00:00'
[2023-08-29T22:12:36.201+0000] {taskinstance.py:1824} ERROR - Task failed with exception
Traceback (most recent call last):
  File "/home/airflow/.local/lib/python3.7/site-packages/airflow/decorators/base.py", line 220, in execute
    return_value = super().execute(context)
  File "/home/airflow/.local/lib/python3.7/site-packages/airflow/operators/python.py", line 181, in execute
    return_value = self.execute_callable()
  File "/home/airflow/.local/lib/python3.7/site-packages/airflow/operators/python.py", line 198, in execute_callable
    return self.python_callable(*self.op_args, **self.op_kwargs)
  File "/opt/airflow/dags/dags_python_with_trigger_rule_eg1.py", line 22, in python_upstream_1
    raise AirflowException('downstream_1 Exception!')
airflow.exceptions.AirflowException: downstream_1 Exception!
[2023-08-29T22:12:36.211+0000] {taskinstance.py:1350} INFO - Marking task as FAILED. dag_id=dags_python_with_trigger_rule_eg1, task_id=python_upstream_1, execution_date=20230829T221233, start_date=20230829T221235, end_date=20230829T221236
[2023-08-29T22:12:36.246+0000] {standard_task_runner.py:109} ERROR - Failed to execute job 162 for task python_upstream_1 (downstream_1 Exception!; 2510)
[2023-08-29T22:12:36.263+0000] {local_task_job_runner.py:225} INFO - Task exited with return code 1
[2023-08-29T22:12:36.306+0000] {taskinstance.py:2653} INFO - 0 downstream tasks scheduled from follow-on schedule check
